Workbook

Sheet Balanço Contab
A1: Entidade: | B1: JJ TEIXEIRA, SA
B2: Wood Engineeing Tailor
B4: Balanço individual a 31 de dezembro | F4: (em euros)
B5: Rubricas | C5: Notas | D5: Anos
D6: 2022 | E6: 2023 | F6: 2024
B7: ATIVO
B8: Ativo não corrente
B9: Ativos fixos tangíveis | C9: 5 | D9: 19459800 | E9: 18666572 | F9: 20729866
B10: Propriedades de investimento | C10: 6 | D10: 78216 | E10: 76393 | F10: 74571
B11: Ativos intangíveis | C11: 7 | D11: 278210 | E11: 261041 | F11: 242369
B12: Participações financeiras - Outros métodos | C12: 8 | D12: 160000 | E12: 166000 | F12: 166000
B13: Outros ativos financeiros | D13: 2392 | E13: 2944 | F13: 2887
B14: Ativos por impostos diferidos | C14: 9 | D14: 3543112 | E14: 2870650 | F14: 3308871
D15: =SUM(D9:D14) -> 23521730 | E15: =SUM(E9:E14) -> 22043600 | F15: =SUM(F9:F14) -> 24524564
B16: Ativo corrente
B17: Inventários | C17: 10 | D17: 2476629 | E17: 2368546 | F17: 2667287
B18: Clientes | C18: 11 | D18: 10993343 | E18: 13433628 | F18: 15033498
B19: Estado e Outros Entes Públicos | C19: 12 | D19: 299077 | E19: 254510 | F19: 764059
B20: Outros créditos a receber | C20: 13 | D20: 4152529 | E20: 5511417 | F20: 7076559
B21: Diferimentos | C21: 14 | D21: 175917 | E21: 187514 | F21: 206335 | G21: Diferimentos: são Gastos a reconhecer (nota 14)
B22: Caixa e depósitos bancários | C22: 4 | D22: 2257927 | E22: 4138413 | F22: 1799870
D23: =SUM(D17:D22) -> 20355422 | E23: =SUM(E17:E22) -> 25894028 | F23: =SUM(F17:F22) -> 27547608
B24: Total do Ativo | D24: =D15+D23 -> 43877152 | E24: =E15+E23 -> 47937627 | F24: =F15+F23 -> 52072172
B25: CAPITAL PRÓPRIO PASSIVO
B26: Capital Próprio
B27: Capital realizado | C27: 15 | D27: 11740455 | E27: 11740455 | F27: 11740455
B28: Prémios de emissão | C28: 17 | D28: 959545 | E28: 959545 | F28: 959545
B29: Reservas Legais | C29: 18 | D29: 658278 | E29: 773685 | F29: 891080
B30: Outras reservas | C30: 16 | D30: 4710221 | E30: 4710221 | F30: 4710221
B31: Resultados Transitados | C31: 19 | D31: -2266539 | E31: -73815 | F31: 2156686
B32: Outras variações no capital próprio | C32: 20 | D32: 2482464 | E32: 1982771 | F32: 1622563
B33: Resultado liquido do período | D33: 2308131 | E33: 2347896 | F33: 2279250
B34: Total do Capital Próprio | D34: =SUM(D27:D33) -> 20592555 | E34: =SUM(E27:E33) -> 22440758 | F34: =SUM(F27:F33) -> 24359800
B36: Passivo
B37: Passivo não corrente
B38: Provisões | D38: 0 | E38: 0 | F38: 0
B39: Financiamentos obtidos | C39: 23 | D39: 10408410 | E39: 9500813 | F39: 13988727
B40: Outras dívidas a pagar | C40: 24 | D40: 3974890 | E40: 3334245 | F40: 1761814
D41: =SUM(D38:D40) -> 14383300 | E41: =SUM(E38:E40) -> 12835058 | F41: =SUM(F38:F40) -> 15750541
B42: Passivo Corrente
...

Sheet Balanço Funcional
A2: Entidade: | B2: JJ Teixeira, S.A.
B4: Balanço Funcional | G4: (em euros)
B5: Rubricas | C5: Notas | E5: Anos
D6: 2021 | E6: 2022 | F6: 2023 | G6: 2024
B7: Aplicações Fixas Líquidas
B8: ='Balanço Contab'!B9 -> Ativos fixos tangíveis | C8: ='Balanço Contab'!C9 -> 5 | D8: 21318266 | E8: ='Balanço Contab'!D9 -> 19459800 | F8: ='Balanço Contab'!E9 -> 18666572 | G8: ='Balanço Contab'!F9 -> 20729866
B9: ='Balanço Contab'!B10 -> Propriedades de investimento | C9: ='Balanço Contab'!C10 -> 6 | D9: 80038 | E9: ='Balanço Contab'!D10 -> 78216 | F9: ='Balanço Contab'!E10 -> 76393 | G9: ='Balanço Contab'!F10 -> 74571
B10: ='Balanço Contab'!B11 -> Ativos intangíveis | C10: ='Balanço Contab'!C11 -> 7 | D10: 312295 | E10: ='Balanço Contab'!D11 -> 278210 | F10: ='Balanço Contab'!E11 -> 261041 | G10: ='Balanço Contab'!F11 -> 242369
B11: ='Balanço Contab'!B12 -> Participações financeiras - Outros métodos | C11: ='Balanço Contab'!C12 -> 8 | D11: 160000 | E11: ='Balanço Contab'!D12 -> 160000 | F11: ='Balanço Contab'!E12 -> 166000 | G11: ='Balanço Contab'!F12 -> 166000
B12: ='Balanço Contab'!B13 -> Outros ativos financeiros | D12: 345 | E12: ='Balanço Contab'!D13 -> 2392 | F12: ='Balanço Contab'!E13 -> 2944 | G12: ='Balanço Contab'!F13 -> 2887
B13: ='Balanço Contab'!B14 -> Ativos por impostos diferidos | C13: ='Balanço Contab'!C14 -> 9 | D13: 3480361 | E13: ='Balanço Contab'!D14 -> 3543112 | F13: ='Balanço Contab'!E14 -> 2870650 | G13: ='Balanço Contab'!F14 -> 3308871
B14: Outros créditos a receber | C14: 13 | D14: 13181 | E14: ='Balanço Contab'!D75 -> 13181 | F14: ='Balanço Contab'!E75 -> 13181 | G14: ='Balanço Contab'!F75 -> 13181 | H14: Cauções (extra exploração; valor constante no triénio)
D15: =SUM(D8:D14) -> 25364486 | E15: =SUM(E8:E14) -> 23534911 | F15: =SUM(F8:F14) -> 22056780 | G15: =SUM(G8:G14) -> 24537744
B16: Necessidades Cíclicas | H16: Ver se a Ativos não correntes detidos para venda entram
B17: ='Balanço Contab'!B17 -> Inventários | C17: ='Balanço Contab'!C17 -> 10 | D17: 2142568 | E17: ='Balanço Contab'!D17 -> 2476629 | F17: ='Balanço Contab'!E17 -> 2368546 | G17: ='Balanço Contab'!F17 -> 2667287
B18: ='Balanço Contab'!B18 -> Clientes | C18: ='Balanço Contab'!C18 -> 11 | D18: 9505101 | E18: ='Balanço Contab'!D18 -> 10993343 | F18: ='Balanço Contab'!E18 -> 13433628 | G18: ='Balanço Contab'!F18 -> 15033498
B19: ='Balanço Contab'!B19 -> Estado e Outros Entes Públicos | C19: ='Balanço Contab'!C19 -> 12 | D19: 247309 | E19: ='Balanço Contab'!D62 -> 299077 | F19: ='Balanço Contab'!E62 -> 254510 | G19: ='Balanço Contab'!F62 -> 581110 | H19: IVA
B20: ='Balanço Contab'!B20 -> Outros créditos a receber | C20: ='Balanço Contab'!C20 -> 13 | D20: =219243+50602+2678539+668447 -> 3616831 | E20: ='Balanço Contab'!D71+'Balanço Contab'!D72+'Balanço Contab'!D73+'Balanço Contab'!D76 -> 4135106 | F20: ='Balanço Contab'!E71+'Balanço Contab'!E72+'Balanço Contab'!E73+'Balanço Contab'!E76 -> 5474774 | G20: ='Balanço Contab'!F71+'Balanço Contab'!F72+'Balanço Contab'!F73+'Balanço Contab'!F76 -> 7063378 | H20: Adiant. fornec.; Adiant. pessoal; Obras plurianuais; Outros
B21: ='Balanço Contab'!B21 -> Diferimentos | C21: ='Balanço Contab'!C21 -> 14 | D21: 135936 | E21: ='Balanço Contab'!D83+'Balanço Contab'!D84 -> 175917 | F21: ='Balanço Contab'!E83+'Balanço Contab'!E84 -> 187514 | G21: ='Balanço Contab'!F83+'Balanço Contab'!F84 -> 206335 | H21: Seguros; Outros
D22: =SUM(D17:D21) -> 15647745 | E22: =SUM(E17:E21) -> 18080072 | F22: =SUM(F17:F21) -> 21718972 | G22: =SUM(G17:G21) -> 25551608
B23: Tesouraria Ativa
B24: Estado e Outros Entes Públicos (IRC) | C24: 12 | D24: 31 | E24: ='Balanço Contab'!D60 -> 0 | F24: ='Balanço Contab'!E60 -> 0 | G24: ='Balanço Contab'!F60 -> 182949
B25: Outros créditos a receber | C25: 13 | D25: 11313 | E25: ='Balanço Contab'!D74 -> 4242 | F25: ='Balanço Contab'!E74 -> 23462 | G25: ='Balanço Contab'!F74 -> 0 | H25: Subsídios
B26: ='Balanço Contab'!B22 -> Caixa e depósitos bancários | C26: 4 | D26: 1461954 | E26: ='Balanço Contab'!D22 -> 2257927 | F26: ='Balanço Contab'!E22 -> 4138413 | G26: ='Balanço Contab'!F22 -> 1799870
D27: =SUM(D24:D26) -> 1473298 | E27: =SUM(E24:E26) -> 2262169 | F27: =SUM(F24:F26) -> 4161875 | G27: =SUM(G24:G26) -> 1982819
B28: ='Balanço Contab'!B24 -> Total do Ativo | D28: =D15+D22+D27 -> 42485529 | E28: =E15+E22+E27 -> 43877152 | F28: =F15+F22+F27 -> 47937627 | G28: =G15+G22+G27 -> 52072172 | I28: =E28-'Balanço Contab'!D24 -> 0 | J28: =F28-'Balanço Contab'!E24 -> 0 | K28: =G28-'Balanço Contab'!F24 -> 0
B29: Recursos Estáveis
B30: ='Balanço Contab'!B26 -> Capital Próprio
B31: ='Balanço Contab'!B27 -> Capital realizado | C31: ='Balanço Contab'!C27 -> 15 | D31: 11740455 | E31: ='Balanço Contab'!D27 -> 11740455 | F31: ='Balanço Contab'!E27 -> 11740455 | G31: ='Balanço Contab'!F27 -> 11740455
B32: ='Balanço Contab'!B28 -> Prémios de emissão | C32: ='Balanço Contab'!C28 -> 17 | D32: 959545 | E32: ='Balanço Contab'!D28 -> 959545 | F32: ='Balanço Contab'!E28 -> 959545 | G32: ='Balanço Contab'!F28 -> 959545
B33: ='Balanço Contab'!B29 -> Reservas Legais | C33: ='Balanço Contab'!C29 -> 18 | D33: 658278 | E33: ='Balanço Contab'!D29 -> 658278 | F33: ='Balanço Contab'!E29 -> 773685 | G33: ='Balanço Contab'!F29 -> 891080
B34: ='Balanço Contab'!B30 -> Outras reservas | C34: ='Balanço Contab'!C30 -> 16 | D34: 4710221 | E34: ='Balanço Contab'!D30 -> 4710221 | F34: ='Balanço Contab'!E30 -> 4710221 | G34: ='Balanço Contab'!F30 -> 4710221
B35: ='Balanço Contab'!B31 -> Resultados Transitados | C35: ='Balanço Contab'!C31 -> 19 | D35: -1804293 | E35: ='Balanço Contab'!D31 -> -2266539 | F35: ='Balanço Contab'!E31 -> -73815 | G35: ='Balanço Contab'!F31 -> 2156686
B36: ='Balanço Contab'!B32 -> Outras variações no capital próprio | C36: ='Balanço Contab'!C32 -> 20 | D36: 3144447 | E36: ='Balanço Contab'!D32 -> 2482464 | F36: ='Balanço Contab'!E32 -> 1982771 | G36: ='Balanço Contab'!F32 -> 1622563
B37: ='Balanço Contab'!B33 -> Resultado liquido do período | D37: -462246 | E37: ='Balanço Contab'!D33 -> 2308131 | F37: ='Balanço Contab'!E33 -> 2347896 | G37: ='Balanço Contab'!F33 -> 2279250
B38: ='Balanço Contab'!B34 -> Total do Capital Próprio | D38: =SUM(D31:D37) -> 18946407 | E38: =SUM(E31:E37) -> 20592555 | F38: =SUM(F31:F37) -> 22440758 | G38: =SUM(G31:G37) -> 24359800
B40: ='Balanço Contab'!B37 -> Passivo não corrente
B41: ='Balanço Contab'!B38 -> Provisões | D41: 0 | E41: ='Balanço Contab'!D38 -> 0 | F41: ='Balanço Contab'!E38 -> 0 | G41: ='Balanço Contab'!F38 -> 0
B42: ='Balanço Contab'!B39 -> Financiamentos obtidos | C42: ='Balanço Contab'!C39 -> 23 | D42: 10522437 | E42: ='Balanço Contab'!D39 -> 10408410 | F42: ='Balanço Contab'!E39 -> 9500813 | G42: ='Balanço Contab'!F39 -> 13988727
B43: ='Balanço Contab'!B40 -> Outras dívidas a pagar | C43: ='Balanço Contab'!C40 -> 24 | D43: 4032293 | E43: ='Balanço Contab'!D40 -> 3974890 | F43: ='Balanço Contab'!E40 -> 3334245 | G43: ='Balanço Contab'!F40 -> 1761814
...

Sheet DR Contab
A2: Entidade: | B2: JJ Teixeira, S.A.
B4: Demonstração dos resultados a 31 de dezembro | F4: (em euros)
B5: RENDIMENTOS E GASTOS | C5: Notas | D5: Anos
D6: 2022 | E6: 2023 | F6: 2024
B7: Vendas e serviços prestados | C7: 25 | D7: 34414527 | E7: 36103943 | F7: 39540477 | G7: =((F7-E7)/E7)*100 -> 9.5184451
B8: Subsídios à exploração | C8: 26 | D8: 71600 | E8: 42589 | F8: 870
B9: Variação nos inventários da produção | C9: 27 | D9: 3248 | E9: -59213 | F9: 131969
B10: Trabalhos para a própria entidade
B11: Custo das mercadorias vendidas e matérias consumidas | C11: 28 | D11: -9270182 | E11: -9474096 | F11: -10429861
B12: Fornecimentos e serviços externos | C12: 29 | D12: -10472728 | E12: -10062717 | F12: -13103785
B13: Gastos com pessoal | C13: 30 | D13: -8709967 | E13: -9570544 | F13: -10311572
B14: Imparidade de inventários (perdas/reversões) | C14: 10 | D14: 24000 | E14: -7482 | F14: 7482
B15: Imparidade de dívidas a receber (perdas/reversões) | C15: 11 | D15: -1074082 | E15: -530467 | F15: -403235
B16: Aumentos/reduções de justo valor | D16: -211 | E16: 91 | F16: -58
B17: Ganhos/Perdas em empresas do grupo
B18: Outros rendimentos e ganhos | C18: 31 | D18: 1262832 | E18: 768393 | F18: 677442
B19: Outros gastos e perdas | C19: 32 | D19: -230470 | E19: -285783 | F19: -346147
B20: Resultado antes de depreciações, gastos de financiamento e impostos | D20: =SUM(D7:D19) -> 6018567 | E20: =SUM(E7:E19) -> 6924714 | F20: =SUM(F7:F19) -> 5763582
B21: Gastos/reversões de depreciação e de amortização | C21: 33 | D21: -3102483 | E21: -2957566 | F21: -2761538
B22: Imparidade de investimentos depreciáveis/amortizáveis (perdas/reversões)
B23: Resultado Operacional (antes de gastos de financiamento e impostos) | D23: =SUM(D20:D22) -> 2916084 | E23: =SUM(E20:E22) -> 3967148 | F23: =SUM(F20:F22) -> 3002044
B24: Juros e rendimentos similares obtidos | C24: 34 | D24: 1595 | E24: 93572 | F24: 47799
B25: Juros de empresas do grupo
B26: Juros e gastos similares suportados | C26: 35 | D26: -635383 | E26: -972006 | F26: -1151303
B27: Resultado antes de impostos | D27: =SUM(D23:D26) -> 2282296 | E27: =SUM(E23:E26) -> 3088714 | F27: =SUM(F23:F26) -> 1898540
B28: Imposto s/ rendimento do período | D28: 25835 | E28: -740818 | F28: 380710
B29: Imposto diferido
B30: Resultado liquido do período | D30: =SUM(D27:D29) -> 2308131 | E30: =SUM(E27:E29) -> 2347896 | F30: =SUM(F27:F29) -> 2279250
D32: =D30-'Balanço Contab'!D33 -> 0 | E32: =E30-'Balanço Contab'!E33 -> 0 | F32: =F30-'Balanço Contab'!F33 -> 0

Sheet DFC
A1: Entidade: | B1: JJ Teixeira, S.A.
B2: Wood Engineeing Tailor
B4: Demonstração dos Fluxos de Caixa a 31 de dezembro | F4: (em euros)
C5: Notas | D5: Anos
D6: 2022 | E6: 2023 | F6: 2024
B7: ATIVIDADES OPERACIONAIS
B8: Recebimentos de Clientes | D8: 32022238 | E8: 35414144 | F8: 33078927
B9: Pagamentos a Fornecedores | D9: -20413424 | E9: -20834983 | F9: -29115362
B10: Pagamentos ao Pessoal | D10: -7735883.1 | E10: -8212829 | F10: -5083582
B11: Fluxo de caixa gerado pelas operações | D11: =SUM(D8:D10) -> 3872930.9 | E11: =SUM(E8:E10) -> 6366332 | F11: =SUM(F8:F10) -> -1120017
B12: Pagamento/Recebimento do imposto sobre o valor acrescentado
B13: Pagamento/Recebimento do imposto sobre o rendimento | D13: -14353 | E13: -36916 | F13: -31714
B14: Outros recebimentos/pagamentos | D14: -890155 | E14: -1479222 | F14: -987583
B15: FLUXO GERADO PELAS ATIVIDADES OPERACIONAIS | D15: =SUM(D11:D14) -> 2968422.9 | E15: =SUM(E11:E14) -> 4850194 | F15: =SUM(F11:F14) -> -2139314
B17: ATIVIDADES DE INVESTIMENTO
B18: Pagamentos de:
B19: - Ativos Fixos Tangíveis | D19: -677259 | E19: -1361396 | F19: -2496379
B20: - Ativos Fixos Intangíveis
B21: - Investimentos Financeiros
B22: - Outros Ativos
B23: - Subsídios ao Investimento
B25: Recebimentos de:
B26: - Ativos Fixos Tangíveis | D26: 216000
B27: - Ativos Fixos Intangíveis
B28: - Investimentos Financeiros | D28: 99
B29: - Outros Ativos
B30: - Subsídios ao Investimento | D30: 693 | E30: 611
B31: - Juros e Rendimentos similares
B32: - Dividendos
B33: FLUXO GERADO PELAS ATIVIDADES INVESTIMENTO | D33: =SUM(D19:D32) -> -460467 | E33: =SUM(E19:E32) -> -1360785 | F33: =SUM(F19:F32) -> -2496379
B35: ATIVIDADES DE FINANCIAMENTO
B36: Recebimentos de:
B37: - Financiamentos Obtidos | D37: 9560728 | E37: 8828515 | F37: 34670956
B38: - Realizações de capital e de outros instrumentos de Capital Próprio
B39: - Cobertura de Prejuízos
B40: - Doações
B41: - Juros e rendimentos similares
B42: - Outras operações de financiamento
B44: Pagamentos de:
B45: - Financiamentos Obtidos | D45: -10675529 | E45: -9433377 | F45: -31319779
...

Sheet Técnicas
A2: Entidade: | B2: JJ Teixeira, S.A.
B4: Balanço individual a 31 de dezembro | D4: Numeros Índice Base Móvel = (rubrica / ano anterior) x 100 | H4: Mapa de Mutação de Valores | K4: Balanço individual a 31 de dezembro | R4: Valores Relativos | U4: Balanço individual a 31 de dezembro | AB4: Índices de Base Fixa (IBF) | AE4: Balanço individual a 31 de dezembro | AL4: Índices de Base Móvel (IBM)
B5: Rubricas | C5: Notas | D5: Anos | G5: Valores Absolutos (€) | K5: Rubricas | L5: Notas | M5: 2022 | O5: 2023 | Q5: 2024 | U5: Rubricas | V5: Notas | W5: 2022 | Y5: 2023 | AA5: 2024 | AE5: Rubricas | AF5: Notas | AG5: 2022 | AI5: 2023 | AK5: 2024
D6: 2022 | E6: 2023 | F6: 2024 | G6: (2023) - (2022) | H6: (2024) - (2023) | M6: Valor (€) | N6: % | O6: Valor (€) | P6: % | Q6: Valor (€) | R6: % | W6: Valor (€) | X6: IBF | Y6: Valor (€) | Z6: IBF | AA6: Valor (€) | AB6: IBF | AG6: Valor (€) | AH6: IBM | AI6: Valor (€) | AJ6: IBM | AK6: Valor (€) | AL6: IBM
B7: ='Balanço Contab'!B7 -> ATIVO | K7: =B7 -> ATIVO | U7: =K7 -> ATIVO | AE7: =U7 -> ATIVO
B8: ='Balanço Contab'!B8 -> Ativo não corrente | K8: =B8 -> Ativo não corrente | U8: =K8 -> Ativo não corrente | AE8: =U8 -> Ativo não corrente
B9: ='Balanço Contab'!B9 -> Ativos fixos tangíveis | D9: ='Balanço Contab'!D9 -> 19459800 | E9: ='Balanço Contab'!E9 -> 18666572 | F9: ='Balanço Contab'!F9 -> 20729866 | G9: =E9-D9 -> -793228.5 | H9: =F9-E9 -> 2063294 | K9: =B9 -> Ativos fixos tangíveis | M9: =D9 -> 19459800 | N9: =M9/$M$24 -> 0.44350645 | O9: =E9 -> 18666572 | P9: =O9/$O$24 -> 0.3893929 | Q9: =F9 -> 20729866 | R9: =Q9/$Q$24 -> 0.39809873 | U9: =B9 -> Ativos fixos tangíveis | W9: =D9 -> 19459800 | X9: =(W9/W9)*100 -> 100 | Y9: =E9 -> 18666572 | Z9: =(Y9/W9)*100 -> 95.923758 | AA9: =F9 -> 20729866 | AB9: =(AA9/W9)*100 -> 106.52661 | AE9: =B9 -> Ativos fixos tangíveis | AG9: =D9 -> 19459800 | AH9: =(AG9/AG9)*100 -> 100 | AI9: =E9 -> 18666572 | AJ9: =(AI9/AG9)*100 -> 95.923758 | AK9: =F9 -> 20729866 | AL9: =(AK9/AI9)*100 -> 111.05342
B10: ='Balanço Contab'!B10 -> Propriedades de investimento | D10: ='Balanço Contab'!D10 -> 78216 | E10: ='Balanço Contab'!E10 -> 76393 | F10: ='Balanço Contab'!F10 -> 74571 | G10: =E10-D10 -> -1823 | H10: =F10-E10 -> -1822 | K10: =B10 -> Propriedades de investimento | M10: =D10 -> 78216 | N10: =M10/$M$24 -> 0.0017826134 | O10: =E10 -> 76393 | P10: =O10/$O$24 -> 0.0015935916 | Q10: =F10 -> 74571 | R10: =Q10/$Q$24 -> 0.0014320701 | U10: =B10 -> Propriedades de investimento | W10: =D10 -> 78216 | X10: =(W10/W10)*100 -> 100 | Y10: =E10 -> 76393 | Z10: =(Y10/W10)*100 -> 97.669275 | AA10: =F10 -> 74571 | AB10: =(AA10/W10)*100 -> 95.339828 | AE10: =B10 -> Propriedades de investimento | AG10: =D10 -> 78216 | AH10: =(AG10/AG10)*100 -> 100 | AI10: =E10 -> 76393 | AJ10: =(AI10/AG10)*100 -> 97.669275 | AK10: =F10 -> 74571 | AL10: =(AK10/AI10)*100 -> 97.614965
B11: ='Balanço Contab'!B11 -> Ativos intangíveis | D11: ='Balanço Contab'!D11 -> 278210 | E11: ='Balanço Contab'!E11 -> 261041 | F11: ='Balanço Contab'!F11 -> 242369 | G11: =E11-D11 -> -17169 | H11: =F11-E11 -> -18672 | K11: =B11 -> Ativos intangíveis | M11: =D11 -> 278210 | N11: =M11/$M$24 -> 0.0063406577 | O11: =E11 -> 261041 | P11: =O11/$O$24 -> 0.0054454302 | Q11: =F11 -> 242369 | R11: =Q11/$Q$24 -> 0.0046544822 | U11: =B11 -> Ativos intangíveis | W11: =D11 -> 278210 | X11: =(W11/W11)*100 -> 100 | Y11: =E11 -> 261041 | Z11: =(Y11/W11)*100 -> 93.828762 | AA11: =F11 -> 242369 | AB11: =(AA11/W11)*100 -> 87.117286 | AE11: =B11 -> Ativos intangíveis | AG11: =D11 -> 278210 | AH11: =(AG11/AG11)*100 -> 100 | AI11: =E11 -> 261041 | AJ11: =(AI11/AG11)*100 -> 93.828762 | AK11: =F11 -> 242369 | AL11: =(AK11/AI11)*100 -> 92.847101
B12: ='Balanço Contab'!B12 -> Participações financeiras - Outros métodos | D12: ='Balanço Contab'!D12 -> 160000 | E12: ='Balanço Contab'!E12 -> 166000 | F12: ='Balanço Contab'!F12 -> 166000 | G12: =E12-D12 -> 6000 | H12: =F12-E12 -> 0 | K12: =B12 -> Participações financeiras - Outros métodos | M12: =D12 -> 160000 | N12: =M12/$M$24 -> 0.0036465448 | O12: =E12 -> 166000 | P12: =O12/$O$24 -> 0.0034628331 | Q12: =F12 -> 166000 | R12: =Q12/$Q$24 -> 0.0031878832 | U12: =B12 -> Participações financeiras - Outros métodos | W12: =D12 -> 160000 | X12: =(W12/W12)*100 -> 100 | Y12: =E12 -> 166000 | Z12: =(Y12/W12)*100 -> 103.75 | AA12: =F12 -> 166000 | AB12: =(AA12/W12)*100 -> 103.75 | AE12: =B12 -> Participações financeiras - Outros métodos | AG12: =D12 -> 160000 | AH12: =(AG12/AG12)*100 -> 100 | AI12: =E12 -> 166000 | AJ12: =(AI12/AG12)*100 -> 103.75 | AK12: =F12 -> 166000 | AL12: =(AK12/AI12)*100 -> 100
B13: ='Balanço Contab'!B13 -> Outros ativos financeiros | D13: ='Balanço Contab'!D13 -> 2392 | E13: ='Balanço Contab'!E13 -> 2944 | F13: ='Balanço Contab'!F13 -> 2887 | G13: =E13-D13 -> 552 | H13: =F13-E13 -> -57 | K13: =B13 -> Outros ativos financeiros | M13: =D13 -> 2392 | N13: =M13/$M$24 -> 5.4515845e-05 | O13: =E13 -> 2944 | P13: =O13/$O$24 -> 6.1413136e-05 | Q13: =F13 -> 2887 | R13: =Q13/$Q$24 -> 5.5442281e-05 | U13: =B13 -> Outros ativos financeiros | W13: =D13 -> 2392 | X13: =(W13/W13)*100 -> 100 | Y13: =E13 -> 2944 | Z13: =(Y13/W13)*100 -> 123.07692 | AA13: =F13 -> 2887 | AB13: =(AA13/W13)*100 -> 120.69398 | AE13: =B13 -> Outros ativos financeiros | AG13: =D13 -> 2392 | AH13: =(AG13/AG13)*100 -> 100 | AI13: =E13 -> 2944 | AJ13: =(AI13/AG13)*100 -> 123.07692 | AK13: =F13 -> 2887 | AL13: =(AK13/AI13)*100 -> 98.063859
B14: ='Balanço Contab'!B14 -> Ativos por impostos diferidos | D14: ='Balanço Contab'!D14 -> 3543112 | E14: ='Balanço Contab'!E14 -> 2870650 | F14: ='Balanço Contab'!F14 -> 3308871 | G14: =E14-D14 -> -672462 | H14: =F14-E14 -> 438221 | K14: =B14 -> Ativos por impostos diferidos | M14: =D14 -> 3543112 | N14: =M14/$M$24 -> 0.080750729 | O14: =E14 -> 2870650 | P14: =O14/$O$24 -> 0.059883023 | Q14: =F14 -> 3308871 | R14: =Q14/$Q$24 -> 0.063543941 | U14: =B14 -> Ativos por impostos diferidos | W14: =D14 -> 3543112 | X14: =(W14/W14)*100 -> 100 | Y14: =E14 -> 2870650 | Z14: =(Y14/W14)*100 -> 81.020583 | AA14: =F14 -> 3308871 | AB14: =(AA14/W14)*100 -> 93.388834 | AE14: =B14 -> Ativos por impostos diferidos | AG14: =D14 -> 3543112 | AH14: =(AG14/AG14)*100 -> 100 | AI14: =E14 -> 2870650 | AJ14: =(AI14/AG14)*100 -> 81.020583 | AK14: =F14 -> 3308871 | AL14: =(AK14/AI14)*100 -> 115.26557
D15: =SUM(D9:D14) -> 23521730 | E15: =SUM(E9:E14) -> 22043600 | F15: =SUM(F9:F14) -> 24524564 | G15: =E15-D15 -> -1478130.5 | H15: =F15-E15 -> 2480964 | M15: =SUM(M9:M14) -> 23521730 | N15: =M15/$M$24 -> 0.53608151 | O15: =SUM(O9:O14) -> 22043600 | P15: =O15/$O$24 -> 0.45983919 | Q15: =SUM(Q9:Q14) -> 24524564 | R15: =Q15/$Q$24 -> 0.47097255 | W15: =SUM(W9:W14) -> 23521730 | X15: =(W15/W15)*100 -> 100 | Y15: =SUM(Y9:Y14) -> 22043600 | Z15: =(Y15/W15)*100 -> 93.715894 | AA15: =SUM(AA9:AA14) -> 24524564 | AB15: =(AA15/W15)*100 -> 104.26343 | AG15: =SUM(AG9:AG14) -> 23521730 | AH15: =(AG15/AG15)*100 -> 100 | AI15: =SUM(AI9:AI14) -> 22043600 | AJ15: =(AI15/AG15)*100 -> 93.715894 | AK15: =SUM(AK9:AK14) -> 24524564 | AL15: =(AK15/AI15)*100 -> 111.2548
B16: ='Balanço Contab'!B16 -> Ativo corrente | K16: =B16 -> Ativo corrente | N16: =M16/$M$24 -> 0 | P16: =O16/$O$24 -> 0 | R16: =Q16/$Q$24 -> 0 | U16: =K16 -> Ativo corrente | AE16: =U16 -> Ativo corrente
B17: ='Balanço Contab'!B17 -> Inventários | D17: ='Balanço Contab'!D17 -> 2476629 | E17: ='Balanço Contab'!E17 -> 2368546 | F17: ='Balanço Contab'!F17 -> 2667287 | G17: =E17-D17 -> -108083 | H17: =F17-E17 -> 298741 | K17: =B17 -> Inventários | M17: =D17 -> 2476629 | N17: =M17/$M$24 -> 0.056444616 | O17: =E17 -> 2368546 | P17: =O17/$O$24 -> 0.049408912 | Q17: =F17 -> 2667287 | R17: =Q17/$Q$24 -> 0.051222887 | U17: =B17 -> Inventários | W17: =D17 -> 2476629 | X17: =(W17/W17)*100 -> 100 | Y17: =E17 -> 2368546 | Z17: =(Y17/W17)*100 -> 95.635882 | AA17: =F17 -> 2667287 | AB17: =(AA17/W17)*100 -> 107.69829 | AE17: =B17 -> Inventários | AG17: =D17 -> 2476629 | AH17: =(AG17/AG17)*100 -> 100 | AI17: =E17 -> 2368546 | AJ17: =(AI17/AG17)*100 -> 95.635882 | AK17: =F17 -> 2667287 | AL17: =(AK17/AI17)*100 -> 112.61284
B18: ='Balanço Contab'!B18 -> Clientes | D18: ='Balanço Contab'!D18 -> 10993343 | E18: ='Balanço Contab'!E18 -> 13433628 | F18: ='Balanço Contab'!F18 -> 15033498 | G18: =E18-D18 -> 2440284.5 | H18: =F18-E18 -> 1599871 | K18: =B18 -> Clientes | M18: =D18 -> 10993343 | N18: =M18/$M$24 -> 0.25054824 | O18: =E18 -> 13433628 | P18: =O18/$O$24 -> 0.28023138 | Q18: =F18 -> 15033498 | R18: =Q18/$Q$24 -> 0.28870504 | U18: =B18 -> Clientes | W18: =D18 -> 10993343 | X18: =(W18/W18)*100 -> 100 | Y18: =E18 -> 13433628 | Z18: =(Y18/W18)*100 -> 122.19784 | AA18: =F18 -> 15033498 | AB18: =(AA18/W18)*100 -> 136.75093 | AE18: =U18 -> Clientes | AG18: =D18 -> 10993343 | AH18: =(AG18/AG18)*100 -> 100 | AI18: =E18 -> 13433628 | AJ18: =(AI18/AG18)*100 -> 122.19784 | AK18: =F18 -> 15033498 | AL18: =(AK18/AI18)*100 -> 111.90945
B19: ='Balanço Contab'!B19 -> Estado e Outros Entes Públicos | D19: ='Balanço Contab'!D19 -> 299077 | E19: ='Balanço Contab'!E19 -> 254510 | F19: ='Balanço Contab'!F19 -> 764059 | G19: =E19-D19 -> -44567 | H19: =F19-E19 -> 509549 | K19: =B19 -> Estado e Outros Entes Públicos | M19: =D19 -> 299077 | N19: =M19/$M$24 -> 0.0068162355 | O19: =E19 -> 254510 | P19: =O19/$O$24 -> 0.0053091906 | Q19: =F19 -> 764059 | R19: =Q19/$Q$24 -> 0.014673077 | U19: =B19 -> Estado e Outros Entes Públicos | W19: =D19 -> 299077 | X19: =(W19/W19)*100 -> 100 | Y19: =E19 -> 254510 | Z19: =(Y19/W19)*100 -> 85.098486 | AA19: =F19 -> 764059 | AB19: =(AA19/W19)*100 -> 255.47234 | AE19: =U19 -> Estado e Outros Entes Públicos | AG19: =D19 -> 299077 | AH19: =(AG19/AG19)*100 -> 100 | AI19: =E19 -> 254510 | AJ19: =(AI19/AG19)*100 -> 85.098486 | AK19: =F19 -> 764059 | AL19: =(AK19/AI19)*100 -> 300.20785
B20: ='Balanço Contab'!B20 -> Outros créditos a receber | D20: ='Balanço Contab'!D20 -> 4152529 | E20: ='Balanço Contab'!E20 -> 5511417 | F20: ='Balanço Contab'!F20 -> 7076559 | G20: =E20-D20 -> 1358888 | H20: =F20-E20 -> 1565142 | K20: =B20 -> Outros créditos a receber | M20: =D20 -> 4152529 | N20: =M20/$M$24 -> 0.094639894 | O20: =E20 -> 5511417 | P20: =O20/$O$24 -> 0.11497058 | Q20: =F20 -> 7076559 | R20: =Q20/$Q$24 -> 0.13589906 | U20: =B20 -> Outros créditos a receber | W20: =D20 -> 4152529 | X20: =(W20/W20)*100 -> 100 | Y20: =E20 -> 5511417 | Z20: =(Y20/W20)*100 -> 132.72435 | AA20: =F20 -> 7076559 | AB20: =(AA20/W20)*100 -> 170.41564 | AE20: =U20 -> Outros créditos a receber | AG20: =D20 -> 4152529 | AH20: =(AG20/AG20)*100 -> 100 | AI20: =E20 -> 5511417 | AJ20: =(AI20/AG20)*100 -> 132.72435 | AK20: =F20 -> 7076559 | AL20: =(AK20/AI20)*100 -> 128.39818
B21: ='Balanço Contab'!B21 -> Diferimentos | D21: ='Balanço Contab'!D21 -> 175917 | E21: ='Balanço Contab'!E21 -> 187514 | F21: ='Balanço Contab'!F21 -> 206335 | G21: =E21-D21 -> 11597 | H21: =F21-E21 -> 18821 | K21: =B21 -> Diferimentos | M21: =D21 -> 175917 | N21: =M21/$M$24 -> 0.0040093076 | O21: =E21 -> 187514 | P21: =O21/$O$24 -> 0.0039116246 | Q21: =F21 -> 206335 | R21: =Q21/$Q$24 -> 0.0039624812 | U21: =B21 -> Diferimentos | W21: =D21 -> 175917 | X21: =(W21/W21)*100 -> 100 | Y21: =E21 -> 187514 | Z21: =(Y21/W21)*100 -> 106.59231 | AA21: =F21 -> 206335 | AB21: =(AA21/W21)*100 -> 117.29111 | AE21: =U21 -> Diferimentos | AG21: =D21 -> 175917 | AH21: =(AG21/AG21)*100 -> 100 | AI21: =E21 -> 187514 | AJ21: =(AI21/AG21)*100 -> 106.59231 | AK21: =F21 -> 206335 | AL21: =(AK21/AI21)*100 -> 110.03712
B22: ='Balanço Contab'!B22 -> Caixa e depósitos bancários | D22: ='Balanço Contab'!D22 -> 2257927 | E22: ='Balanço Contab'!E22 -> 4138413 | F22: ='Balanço Contab'!F22 -> 1799870 | G22: =E22-D22 -> 1880486 | H22: =F22-E22 -> -2338543 | K22: =B22 -> Caixa e depósitos bancários | M22: =D22 -> 2257927 | N22: =M22/$M$24 -> 0.0514602 | O22: =E22 -> 4138413 | P22: =O22/$O$24 -> 0.086329117 | Q22: =F22 -> 1799870 | R22: =Q22/$Q$24 -> 0.034564911 | U22: =B22 -> Caixa e depósitos bancários | W22: =D22 -> 2257927 | X22: =(W22/W22)*100 -> 100 | Y22: =E22 -> 4138413 | Z22: =(Y22/W22)*100 -> 183.28374 | AA22: =F22 -> 1799870 | AB22: =(AA22/W22)*100 -> 79.713383 | AE22: =U22 -> Caixa e depósitos bancários | AG22: =D22 -> 2257927 | AH22: =(AG22/AG22)*100 -> 100 | AI22: =E22 -> 4138413 | AJ22: =(AI22/AG22)*100 -> 183.28374 | AK22: =F22 -> 1799870 | AL22: =(AK22/AI22)*100 -> 43.491793
D23: =SUM(D17:D22) -> 20355422 | E23: =SUM(E17:E22) -> 25894028 | F23: =SUM(F17:F22) -> 27547608 | G23: =E23-D23 -> 5538605.5 | H23: =F23-E23 -> 1653581 | M23: =SUM(M17:M22) -> 20355422 | N23: =M23/$M$24 -> 0.46391849 | O23: =SUM(O17:O22) -> 25894028 | P23: =O23/$O$24 -> 0.54016081 | Q23: =SUM(Q17:Q22) -> 27547608 | R23: =Q23/$Q$24 -> 0.52902745 | W23: =SUM(W17:W22) -> 20355422 | X23: =(W23/W23)*100 -> 100 | Y23: =SUM(Y17:Y22) -> 25894028 | Z23: =(Y23/W23)*100 -> 127.20949 | AA23: =SUM(AA17:AA22) -> 27547608 | AB23: =(AA23/W23)*100 -> 135.33303 | AG23: =SUM(AG17:AG22) -> 20355422 | AH23: =(AG23/AG23)*100 -> 100 | AI23: =SUM(AI17:AI22) -> 25894028 | AJ23: =(AI23/AG23)*100 -> 127.20949 | AK23: =SUM(AK17:AK22) -> 27547608 | AL23: =(AK23/AI23)*100 -> 106.38596
B24: ='Balanço Contab'!B24 -> Total do Ativo | D24: =D15+D23 -> 43877152 | E24: =E15+E23 -> 47937627 | F24: =F15+F23 -> 52072172 | G24: =E24-D24 -> 4060475 | H24: =F24-E24 -> 4134545 | K24: =B24 -> Total do Ativo | M24: =M15+M23 -> 43877152 | N24: =M24/$M$24 -> 1 | O24: =O15+O23 -> 47937627 | P24: =O24/$O$24 -> 1 | Q24: =Q15+Q23 -> 52072172 | R24: =Q24/$Q$24 -> 1 | U24: =K24 -> Total do Ativo | W24: =W15+W23 -> 43877152 | X24: =(W24/W24)*100 -> 100 | Y24: =Y15+Y23 -> 47937627 | Z24: =(Y24/W24)*100 -> 109.25419 | AA24: =AA15+AA23 -> 52072172 | AB24: =(AA24/W24)*100 -> 118.67719 | AE24: =U24 -> Total do Ativo | AG24: =AG15+AG23 -> 43877152 | AH24: =(AG24/AG24)*100 -> 100 | AI24: =AI15+AI23 -> 47937627 | AJ24: =(AI24/AG24)*100 -> 109.25419 | AK24: =AK15+AK23 -> 52072172 | AL24: =(AK24/AI24)*100 -> 108.62484
B25: Rubricas | C25: Notas | D25: Anos | G25: Valores Absolutos (€) | K25: Rubricas | L25: Notas | M25: 2022 | O25: 2023 | Q25: 2024 | U25: Rubricas | V25: Notas | W25: 2022 | Y25: 2023 | AA25: 2024 | AE25: Rubricas | AF25: Notas | AG25: 2022 | AI25: 2023 | AK25: 2024
D26: 2022 | E26: 2023 | F26: 2024 | G26: (2023) - (2022) | H26: (2024) - (2023) | M26: Valor (€) | N26: % | O26: Valor (€) | P26: % | Q26: Valor (€) | R26: % | W26: Valor (€) | X26: IBF | Y26: Valor (€) | Z26: IBF | AA26: Valor (€) | AB26: IBF | AG26: Valor (€) | AH26: IBM | AI26: Valor (€) | AJ26: IBM | AK26: Valor (€) | AL26: IBM
B27: ='Balanço Contab'!B25 -> CAPITAL PRÓPRIO PASSIVO | K27: =B27 -> CAPITAL PRÓPRIO PASSIVO | U27: =K27 -> CAPITAL PRÓPRIO PASSIVO | AE27: =U27 -> CAPITAL PRÓPRIO PASSIVO
B28: ='Balanço Contab'!B26 -> Capital Próprio | K28: =B28 -> Capital Próprio | U28: =K28 -> Capital Próprio | AE28: =U28 -> Capital Próprio
B29: ='Balanço Contab'!B27 -> Capital realizado | D29: ='Balanço Contab'!D27 -> 11740455 | E29: ='Balanço Contab'!E27 -> 11740455 | F29: ='Balanço Contab'!F27 -> 11740455 | G29: =E29-D29 -> 0 | H29: =F29-E29 -> 0 | K29: =B29 -> Capital realizado | M29: =D29 -> 11740455 | N29: =M29/$M$53 -> 0.26757559 | O29: =E29 -> 11740455 | P29: =O29/$O$53 -> 0.24491106 | Q29: =F29 -> 11740455 | R29: =Q29/$Q$53 -> 0.22546505 | U29: =B29 -> Capital realizado | W29: =D29 -> 11740455 | X29: =(W29/W29)*100 -> 100 | Y29: =E29 -> 11740455 | Z29: =(Y29/W29)*100 -> 100 | AA29: =F29 -> 11740455 | AB29: =(AA29/W29)*100 -> 100 | AE29: =B29 -> Capital realizado | AG29: =D29 -> 11740455 | AH29: =(AG29/AG29)*100 -> 100 | AI29: =E29 -> 11740455 | AJ29: =(AI29/AG29)*100 -> 100 | AK29: =F29 -> 11740455 | AL29: =(AK29/AI29)*100 -> 100
B30: ='Balanço Contab'!B28 -> Prémios de emissão | D30: ='Balanço Contab'!D28 -> 959545 | E30: ='Balanço Contab'!E28 -> 959545 | F30: ='Balanço Contab'!F28 -> 959545 | G30: =E30-D30 -> 0 | H30: =F30-E30 -> 0 | K30: =B30 -> Prémios de emissão | M30: =D30 -> 959545 | N30: =M30/$M$53 -> 0.021868899 | O30: =E30 -> 959545 | P30: =O30/$O$53 -> 0.020016531 | Q30: =F30 -> 959545 | R30: =Q30/$Q$53 -> 0.018427213 | U30: =B30 -> Prémios de emissão | W30: =D30 -> 959545 | X30: =(W30/W30)*100 -> 100 | Y30: =E30 -> 959545 | Z30: =(Y30/W30)*100 -> 100 | AA30: =F30 -> 959545 | AB30: =(AA30/W30)*100 -> 100 | AE30: =B30 -> Prémios de emissão | AG30: =D30 -> 959545 | AH30: =(AG30/AG30)*100 -> 100 | AI30: =E30 -> 959545 | AJ30: =(AI30/AG30)*100 -> 100 | AK30: =F30 -> 959545 | AL30: =(AK30/AI30)*100 -> 100
B31: ='Balanço Contab'!B29 -> Reservas Legais | D31: ='Balanço Contab'!D29 -> 658278 | E31: ='Balanço Contab'!E29 -> 773685 | F31: ='Balanço Contab'!F29 -> 891080 | G31: =E31-D31 -> 115407 | H31: =F31-E31 -> 117395 | K31: =B31 -> Reservas Legais | M31: =D31 -> 658278 | N31: =M31/$M$53 -> 0.015002751 | O31: =E31 -> 773685 | P31: =O31/$O$53 -> 0.01613941 | Q31: =F31 -> 891080 | R31: =Q31/$Q$53 -> 0.017112403 | U31: =B31 -> Reservas Legais | W31: =D31 -> 658278 | X31: =(W31/W31)*100 -> 100 | Y31: =E31 -> 773685 | Z31: =(Y31/W31)*100 -> 117.53165 | AA31: =F31 -> 891080 | AB31: =(AA31/W31)*100 -> 135.3653 | AE31: =B31 -> Reservas Legais | AG31: =D31 -> 658278 | AH31: =(AG31/AG31)*100 -> 100 | AI31: =E31 -> 773685 | AJ31: =(AI31/AG31)*100 -> 117.53165 | AK31: =F31 -> 891080 | AL31: =(AK31/AI31)*100 -> 115.17349
B32: ='Balanço Contab'!B30 -> Outras reservas | D32: ='Balanço Contab'!D30 -> 4710221 | E32: ='Balanço Contab'!E30 -> 4710221 | F32: ='Balanço Contab'!F30 -> 4710221 | G32: =E32-D32 -> 0 | H32: =F32-E32 -> 0 | K32: =B32 -> Outras reservas | M32: =D32 -> 4710221 | N32: =M32/$M$53 -> 0.1073502 | O32: =E32 -> 4710221 | P32: =O32/$O$53 -> 0.098257283 | Q32: =F32 -> 4710221 | R32: =Q32/$Q$53 -> 0.090455628 | U32: =B32 -> Outras reservas | W32: =D32 -> 4710221 | X32: =(W32/W32)*100 -> 100 | Y32: =E32 -> 4710221 | Z32: =(Y32/W32)*100 -> 100 | AA32: =F32 -> 4710221 | AB32: =(AA32/W32)*100 -> 100 | AE32: =B32 -> Outras reservas | AG32: =D32 -> 4710221 | AH32: =(AG32/AG32)*100 -> 100 | AI32: =E32 -> 4710221 | AJ32: =(AI32/AG32)*100 -> 100 | AK32: =F32 -> 4710221 | AL32: =(AK32/AI32)*100 -> 100
B33: ='Balanço Contab'!B31 -> Resultados Transitados | D33: ='Balanço Contab'!D31 -> -2266539 | E33: ='Balanço Contab'!E31 -> -73815 | F33: ='Balanço Contab'!F31 -> 2156686 | G33: =E33-D33 -> 2192724 | H33: =F33-E33 -> 2230501 | K33: =B33 -> Resultados Transitados | M33: =D33 -> -2266539 | N33: =M33/$M$53 -> -0.051656475 | O33: =E33 -> -73815 | P33: =O33/$O$53 -> -0.0015398134 | Q33: =F33 -> 2156686 | R33: =Q33/$Q$53 -> 0.041417247 | U33: =B33 -> Resultados Transitados | W33: =D33 -> -2266539 | X33: =(W33/W33)*100 -> 100 | Y33: =E33 -> -73815 | AA33: =F33 -> 2156686 | AE33: =B33 -> Resultados Transitados | AG33: =D33 -> -2266539 | AH33: =(AG33/AG33)*100 -> 100 | AI33: =E33 -> -73815 | AK33: =F33 -> 2156686
B34: ='Balanço Contab'!B32 -> Outras variações no capital próprio | D34: ='Balanço Contab'!D32 -> 2482464 | E34: ='Balanço Contab'!E32 -> 1982771 | F34: ='Balanço Contab'!F32 -> 1622563 | G34: =E34-D34 -> -499693 | H34: =F34-E34 -> -360208 | K34: =B34 -> Outras variações no capital próprio | M34: =D34 -> 2482464 | N34: =M34/$M$53 -> 0.056577601 | O34: =E34 -> 1982771 | P34: =O34/$O$53 -> 0.041361476 | Q34: =F34 -> 1622563 | R34: =Q34/$Q$53 -> 0.031159887 | U34: =B34 -> Outras variações no capital próprio | W34: =D34 -> 2482464 | X34: =(W34/W34)*100 -> 100 | Y34: =E34 -> 1982771 | Z34: =(Y34/W34)*100 -> 79.871088 | AA34: =F34 -> 1622563 | AB34: =(AA34/W34)*100 -> 65.360988 | AE34: =B34 -> Outras variações no capital próprio | AG34: =D34 -> 2482464 | AH34: =(AG34/AG34)*100 -> 100 | AI34: =E34 -> 1982771 | AJ34: =(AI34/AG34)*100 -> 79.871088 | AK34: =F34 -> 1622563 | AL34: =(AK34/AI34)*100 -> 81.833101
B35: ='Balanço Contab'!B33 -> Resultado liquido do período | D35: ='Balanço Contab'!D33 -> 2308131 | E35: ='Balanço Contab'!E33 -> 2347896 | F35: ='Balanço Contab'!F33 -> 2279250 | G35: =E35-D35 -> 39765 | H35: =F35-E35 -> -68646 | K35: =B35 -> Resultado liquido do período | M35: =D35 -> 2308131 | N35: =M35/$M$53 -> 0.052604394 | O35: =E35 -> 2347896 | P35: =O35/$O$53 -> 0.048978144 | Q35: =F35 -> 2279250 | R35: =Q35/$Q$53 -> 0.04377098 | U35: =B35 -> Resultado liquido do período | W35: =D35 -> 2308131 | X35: =(W35/W35)*100 -> 100 | Y35: =E35 -> 2347896 | Z35: =(Y35/W35)*100 -> 101.72282 | AA35: =F35 -> 2279250 | AB35: =(AA35/W35)*100 -> 98.748728 | AE35: =B35 -> Resultado liquido do período | AG35: =D35 -> 2308131 | AH35: =(AG35/AG35)*100 -> 100 | AI35: =E35 -> 2347896 | AJ35: =(AI35/AG35)*100 -> 101.72282 | AK35: =F35 -> 2279250 | AL35: =(AK35/AI35)*100 -> 97.076276
B36: ='Balanço Contab'!B34 -> Total do Capital Próprio | D36: =SUM(D29:D35) -> 20592555 | E36: =SUM(E29:E35) -> 22440758 | F36: =SUM(F29:F35) -> 24359800 | G36: =E36-D36 -> 1848203 | H36: =F36-E36 -> 1919042 | K36: =B36 -> Total do Capital Próprio | M36: =SUM(M29:M35) -> 20592555 | N36: =M36/$M$53 -> 0.46932296 | O36: =SUM(O29:O35) -> 22440758 | P36: =O36/$O$53 -> 0.46812409 | Q36: =SUM(Q29:Q35) -> 24359800 | R36: =Q36/$Q$53 -> 0.46780841 | U36: =K36 -> Total do Capital Próprio | W36: =M36 -> 20592555 | X36: =(W36/W36)*100 -> 100 | Y36: =O36 -> 22440758 | Z36: =(Y36/W36)*100 -> 108.9751 | AA36: =Q36 -> 24359800 | AB36: =(AA36/W36)*100 -> 118.29421 | AE36: =U36 -> Total do Capital Próprio | AG36: =SUM(AG29:AG35) -> 20592555 | AH36: =(AG36/AG36)*100 -> 100 | AI36: =SUM(AI29:AI35) -> 22440758 | AJ36: =(AI36/AG36)*100 -> 108.9751 | AK36: =SUM(AK29:AK35) -> 24359800 | AL36: =(AK36/AI36)*100 -> 108.55159
N37: =M37/$M$53 -> 0 | P37: =O37/$O$53 -> 0 | R37: =Q37/$Q$53 -> 0
B38: ='Balanço Contab'!B36 -> Passivo | K38: =B38 -> Passivo | N38: =M38/$M$53 -> 0 | P38: =O38/$O$53 -> 0 | R38: =Q38/$Q$53 -> 0 | U38: =K38 -> Passivo | AE38: =U38 -> Passivo
B39: ='Balanço Contab'!B37 -> Passivo não corrente | K39: =B39 -> Passivo não corrente | N39: =M39/$M$53 -> 0 | P39: =O39/$O$53 -> 0 | R39: =Q39/$Q$53 -> 0 | U39: =K39 -> Passivo não corrente | AE39: =U39 -> Passivo não corrente
B40: ='Balanço Contab'!B38 -> Provisões | D40: ='Balanço Contab'!D38 -> 0 | E40: ='Balanço Contab'!E38 -> 0 | F40: ='Balanço Contab'!F38 -> 0 | G40: =E40-D40 -> 0 | H40: =F40-E40 -> 0 | K40: =B40 -> Provisões | M40: =D40 -> 0 | N40: =M40/$M$53 -> 0 | O40: =E40 -> 0 | P40: =O40/$O$53 -> 0 | Q40: =F40 -> 0 | R40: =Q40/$Q$53 -> 0 | U40: =B40 -> Provisões | W40: =D40 -> 0 | Y40: =E40 -> 0 | AA40: =F40 -> 0 | AE40: =B40 -> Provisões | AG40: =D40 -> 0 | AI40: =E40 -> 0 | AK40: =F40 -> 0
B41: ='Balanço Contab'!B39 -> Financiamentos obtidos | D41: ='Balanço Contab'!D39 -> 10408410 | E41: ='Balanço Contab'!E39 -> 9500813 | F41: ='Balanço Contab'!F39 -> 13988727 | G41: =E41-D41 -> -907597 | H41: =F41-E41 -> 4487914 | K41: =B41 -> Financiamentos obtidos | M41: =D41 -> 10408410 | N41: =M41/$M$53 -> 0.23721708 | O41: =E41 -> 9500813 | P41: =O41/$O$53 -> 0.19819114 | Q41: =F41 -> 13988727 | R41: =Q41/$Q$53 -> 0.26864113 | U41: =B41 -> Financiamentos obtidos | W41: =D41 -> 10408410 | X41: =(W41/W41)*100 -> 100 | Y41: =E41 -> 9500813 | Z41: =(Y41/W41)*100 -> 91.280157 | AA41: =F41 -> 13988727 | AB41: =(AA41/W41)*100 -> 134.39831 | AE41: =B41 -> Financiamentos obtidos | AG41: =D41 -> 10408410 | AH41: =(AG41/AG41)*100 -> 100 | AI41: =E41 -> 9500813 | AJ41: =(AI41/AG41)*100 -> 91.280157 | AK41: =F41 -> 13988727 | AL41: =(AK41/AI41)*100 -> 147.23716
B42: ='Balanço Contab'!B40 -> Outras dívidas a pagar | D42: ='Balanço Contab'!D40 -> 3974890 | E42: ='Balanço Contab'!E40 -> 3334245 | F42: ='Balanço Contab'!F40 -> 1761814 | G42: =E42-D42 -> -640645 | H42: =F42-E42 -> -1572431 | K42: =B42 -> Outras dívidas a pagar | M42: =D42 -> 3974890 | N42: =M42/$M$53 -> 0.09059134 | O42: =E42 -> 3334245 | P42: =O42/$O$53 -> 0.069553818 | Q42: =F42 -> 1761814 | R42: =Q42/$Q$53 -> 0.033834079 | U42: =B42 -> Outras dívidas a pagar | W42: =D42 -> 3974890 | X42: =(W42/W42)*100 -> 100 | Y42: =E42 -> 3334245 | Z42: =(Y42/W42)*100 -> 83.882699 | AA42: =F42 -> 1761814 | AB42: =(AA42/W42)*100 -> 44.323591 | AE42: =B42 -> Outras dívidas a pagar | AG42: =D42 -> 3974890 | AH42: =(AG42/AG42)*100 -> 100 | AI42: =E42 -> 3334245 | AJ42: =(AI42/AG42)*100 -> 83.882699 | AK42: =F42 -> 1761814 | AL42: =(AK42/AI42)*100 -> 52.839968
...

Sheet Folha1

Sheet Equilibrío Financeiro
B2: Quadro E.2: Síntese dos valores do balanço funcional e cálculos auxiliares | G2: (em euros)
B3: Rubricas | C3: Notas | D3: Anos
D4: 2021 (I) | E4: 2022 | F4: 2023 | G4: 2024
B5: AFL | D5: =+'Balanço Funcional'!D15 -> 25364486 | E5: =+'Balanço Funcional'!E15 -> 23534911 | F5: =+'Balanço Funcional'!F15 -> 22056780 | G5: =+'Balanço Funcional'!G15 -> 24537744
B6: AFL Exploração | D6: =+'Balanço Funcional'!D8+'Balanço Funcional'!D10 -> 21630561 | E6: =+'Balanço Funcional'!E8+'Balanço Funcional'!E10 -> 19738010 | F6: =+'Balanço Funcional'!F8+'Balanço Funcional'!F10 -> 18927612 | G6: =+'Balanço Funcional'!G8+'Balanço Funcional'!G10 -> 20972234 | H6: AFT + Inangíveis
B7: AFL Exploração média do período | D7: ----- | E7: =(E6+D6)/2 -> 20684286 | F7: =(F6+E6)/2 -> 19332811 | G7: =(G6+F6)/2 -> 19949924
B8: Inventários | D8: =+'Balanço Funcional'!D17 -> 2142568 | E8: =+'Balanço Funcional'!E17 -> 2476629 | F8: =+'Balanço Funcional'!F17 -> 2368546 | G8: =+'Balanço Funcional'!G17 -> 2667287
B9: Inventários média do período | D9: ----- | E9: =(D8+E8)/2 -> 2309598.5 | F9: =(E8+F8)/2 -> 2422587.5 | G9: =(F8+G8)/2 -> 2517916.5
B10: Matérias primas e mercadorias | D10: 2031389 | E10: 2362202 | F10: 2313333 | G10: 2480109 | H10: Ver se os subprodutos entram ou não/mercadorias
B11: Matérias primas e mercadorias média do período | D11: ----- | E11: =(D10+E10)/2 -> 2196795.5 | F11: =(E10+F10)/2 -> 2337767.5 | G11: =(F10+G10)/2 -> 2396721
B12: Clientes | D12: =+'Balanço Funcional'!D18 -> 9505101 | E12: =+'Balanço Funcional'!E18 -> 10993343 | F12: =+'Balanço Funcional'!F18 -> 13433628 | G12: =+'Balanço Funcional'!G18 -> 15033498
B13: Adiantamentos de clientes | D13: =+'Balanço Funcional'!D48 -> 288801 | E13: =+'Balanço Funcional'!E48 -> 174400 | F13: =+'Balanço Funcional'!F48 -> 1889441 | G13: =+'Balanço Funcional'!G48 -> 1863058
B14: (Clientes - Adiantamentos de clientes) média do período | D14: ----- | E14: =((D12-D13)+(E12-E13))/2 -> 10017622 | F14: =((E12-E13)+(F12-F13))/2 -> 11181565 | G14: =((F12-F13)+(G12-G13))/2 -> 12357314
B15: Meios financeiros líquidos (MFL) | D15: =+'Balanço Funcional'!D26 -> 1461954 | E15: =+'Balanço Funcional'!E26 -> 2257927 | F15: =+'Balanço Funcional'!F26 -> 4138413 | G15: =+'Balanço Funcional'!G26 -> 1799870 | H15: Caixa e DO
B16: Ativo corrente (NC+TA) | D16: =+'Balanço Funcional'!D22+'Balanço Funcional'!D27 -> 17121043 | E16: =+'Balanço Funcional'!E22+'Balanço Funcional'!E27 -> 20342241 | F16: =+'Balanço Funcional'!F22+'Balanço Funcional'!F27 -> 25880846 | G16: =+'Balanço Funcional'!G22+'Balanço Funcional'!G27 -> 27534428
B17: Ativo corrente média do período | D17: ----- | E17: =(E16+D16)/2 -> 18731642 | F17: =(F16+E16)/2 -> 23111544 | G17: =(G16+F16)/2 -> 26707637
B18: Total do ativo | D18: =+'Balanço Funcional'!D28 -> 42485529 | E18: =+'Balanço Funcional'!E28 -> 43877152 | F18: =+'Balanço Funcional'!F28 -> 47937627 | G18: =+'Balanço Funcional'!G28 -> 52072172
B19: Total do ativo média do período | D19: ----- | E19: =(D18+E18)/2 -> 43181340 | F19: =(E18+F18)/2 -> 45907390 | G19: =(F18+G18)/2 -> 50004900
B21: Capital próprio | D21: =+'Balanço Funcional'!D38 -> 18946407 | E21: =+'Balanço Funcional'!E38 -> 20592555 | F21: =+'Balanço Funcional'!F38 -> 22440758 | G21: =+'Balanço Funcional'!G38 -> 24359800
B22: Capital próprio média do período | D22: ----- | E22: =(D21+E21)/2 -> 19769481 | F22: =(E21+F21)/2 -> 21516656 | G22: =(F21+G21)/2 -> 23400279
B23: Capital próprio excluindo o RLP (N) | D23: ='Balanço Funcional'!D38-('Balanço Funcional'!D37) -> 19408653 | E23: ='Balanço Funcional'!E38-'Balanço Funcional'!E37 -> 18284424 | F23: =+'Balanço Funcional'!F38-'Balanço Funcional'!F37 -> 20092862 | G23: ='Balanço Funcional'!G38-'Balanço Funcional'!G37 -> 22080550
B24: Capital Próprio excluindo o RLP (N) média do período | C24: (II) | D24: ----- | E24: =(E23+D23)/2 -> 18846538 | F24: =(F23+E23)/2 -> 19188643 | G24: =(G23+F23)/2 -> 21086706 | H24: ver se é o de sem com o RLP ou sem o rLP
B25: Passivo não corrente | D25: =+'Balanço Funcional'!D44 -> 14554730 | E25: =+'Balanço Funcional'!E44 -> 14383300 | F25: =+'Balanço Funcional'!F44 -> 12835058 | G25: =+'Balanço Funcional'!G44 -> 15750541
B26: Recursos estáveis | D26: =+'Balanço Funcional'!D45 -> 33501137 | E26: =+'Balanço Funcional'!E45 -> 34975855 | F26: =+'Balanço Funcional'!F45 -> 35275816 | G26: =+'Balanço Funcional'!G45 -> 40110341
B27: Fornecedores | D27: =+'Balanço Funcional'!D47 -> 710998 | E27: =+'Balanço Funcional'!E47 -> 1415895 | F27: =+'Balanço Funcional'!F47 -> 633029 | G27: =+'Balanço Funcional'!G47 -> 721181
B28: Adiantamentos a fornecedores | D28: 219243 | E28: =+'Balanço Contab'!D71 -> 159197 | F28: =+'Balanço Contab'!E71 -> 154858 | G28: =+'Balanço Contab'!F71 -> 387998 | H28: Nota 13 do Anexo
B29: (Fornec. - Adiantamentos a fornec.) média do período | D29: ----- | E29: =((D27-D28)+(E27-E28))/2 -> 874226.5 | F29: =((E27-E28)+(F27-F28))/2 -> 867434.5 | G29: =((F27-F28)+(G27-G28))/2 -> 405677
B30: Passivo corrente (RC+TP) | D30: =+'Balanço Funcional'!D52+'Balanço Funcional'!D56 -> 9059375 | E30: ='Balanço Funcional'!E52+'Balanço Funcional'!E56 -> 8901297 | F30: =+'Balanço Funcional'!F52+'Balanço Funcional'!F56 -> 12661811 | G30: =+'Balanço Funcional'!G52+'Balanço Funcional'!G56 -> 11961831
B31: Total Cap. próprio + Passivo | D31: =+'Balanço Funcional'!D58 -> 42560512 | E31: =+'Balanço Funcional'!E58 -> 43877152 | F31: =+'Balanço Funcional'!F58 -> 47937627 | G31: =+'Balanço Funcional'!G58 -> 52072172
B32: (Total do Cap. próprio + Passivo) média do período | D32: ----- | E32: =(D31+E31)/2 -> 43218832 | F32: =(E31+F31)/2 -> 45907390 | G32: =(F31+G31)/2 -> 50004900
B34: Notas:
B35: (I) A consideração do ano 2021 tem como objetivo calcular os valores da média do período para os anos 2022, 2023, 2024.
B36: (II) No cálculo do valor do Capital Próprio excluindo o RLP (N) média do período apenas é retirado o RLP do ano em questão (ano (N)).
B38: Quadro E.3: Síntese dos valores da demostração dos resultados e cálculos auxiliares | G38: (em euros)
B39: Rubricas | C39: Notas | D39: Anos
D40: 2021 (III) | E40: 2022 | F40: 2023 | G40: 2024
B41: Volume de negócios | C41: (IV) | D41: ---- | E41: =+'DR Contab'!D7 -> 34414527 | F41: =+'DR Contab'!E7 -> 36103943 | G41: =+'DR Contab'!F7 -> 39540477
B42: Volume de negócios com IVA | C42: (V) | D42: ---- | E42: =E61*1.23+E62 -> 40430186 | F42: =F61*1.23+F62 -> 41916678 | G42: =G61*1.23+G62 -> 45724608 | H42: VN com IVA = VN mercado interno x 1,23 +VN mercado externo
B43: CMVMC | D43: ---- | E43: =-'DR Contab'!D11 -> 9270182 | F43: =-'DR Contab'!E11 -> 9474096 | G43: =-'DR Contab'!F11 -> 10429861 | H43: DR | I43: ver se é menosl ou masi
B44: Compras | D44: ---- | E44: 9537531 | F44: 9425227 | G44: 10596637 | H44: Nota 28 Anexo
...

Sheet Inf adicionais
A1: Informações adicionais
B3: Informações sobre o volume de negócios (VN)
C5: 2022 | D5: 2023 | E5: 2024
B6: Mercado interno | C6: 26155041 | D6: 25272760 | E6: 26887524
B7: Mercado externo | C7: 8259486 | D7: 10831183 | E7: 12652953
B8: Total VN | C8: =C6+C7 -> 34414527 | D8: =D6+D7 -> 36103943 | E8: =E6+E7 -> 39540477
B11: Informações sobre compras e FSE
C13: 2022 | D13: 2023 | E13: 2024
B14: Mercado interno
B15: Compras | C15: 5722519 | D15: 5843641 | E15: 6146049
B16: FSE | C16: =-('DR Contab'!D12) -> 10472728 | D16: =-('DR Contab'!E12) -> 10062717 | E16: =-('DR Contab'!F12) -> 13103785
B17: Mercado externo
B18: Compras | C18: 3815012 | D18: 3581586 | E18: 4450588
B19: FSE | C19: 0 | D19: 0 | E19: 0
B22: Taxas de IVA aplicadas às vendas, serviços prestados, compras e FSE
B23: Rubricas | C23: Anos
C24: 2022 | D24: 2023 | E24: 2024
B25: Volume de negócios (vendas e serviços prest.) | C25: 0.23 | D25: 0.23 | E25: 0.23
B26: Compras | C26: 0.23 | D26: 0.23 | E26: 0.23
B27: FSE (exceto água) | C27: 0.23 | D27: 0.23 | E27: 0.23
B28: FSE - água | C28: 0.06 | D28: 0.06 | E28: 0.06
